<?xml version="1.0"?>
<robot name="zadanie2" xmlns:xacro="http://www.ros.org/wiki/xacro">
	<xacro:property name="param" value="${load_yaml('../config/urdf.yaml')}"/>
	<xacro:property name="width" value="0.1"/>
	<xacro:property name="radius" value="0.1"/>
	
	<link name="base_link">
		<visual>
			<geometry>
				<cylinder length="0.2" radius="0.2"/>
			</geometry>
		</visual>
	</link>
	
	
	<link name="link_nr_1">
		<visual>
			<geometry>
				<cylinder length="${param['i1']['length']}" radius="${radius}" />
			</geometry>
		</visual>
	</link>
	
	
	<link name="link_nr_2">
		<visual>
			<geometry>
				<cylinder length="${param['i2']['length']}" radius="${radius}"/>
			</geometry>
		</visual>
	</link>
	
	
	<link name="tool">
		<visual>
			<geometry>
				<sphere radius="0.1"/>
			</geometry>
		</visual>
	</link>



	<joint name="joint_1" type="continuous">
		<parent link="base_link"/>
		<child link="link_nr_1"/>
		<origin  rpy="${param['i1']['rpy']}" xyz="${param['i1']['xyz']}"/>
		<axis xyz="0 0 1"/>
	</joint>
	
	<joint name="joint_2" type="continuous">
		<parent link="link_nr_1"/>
		<child link="link_nr_2"/>
		<origin rpy="${param['i2']['rpy']}" xyz="${param['i2']['xyz']}"/>
		<axis xyz="0 0 1"/>
	</joint>
	
	<joint name="joint_3" type="prismatic">
		<parent link="link_nr_2"/>
		<child link="tool"/>
		<limit effort="1000.0" lower="0" upper="1" velocity="0.5"/>
		<origin  rpy="${param['i3']['rpy']}" xyz="${param['i3']['xyz']}"/>
		<axis xyz="0 0 1"/>
	</joint>

</robot>
